File: Data/ARL/Fulin/Ti_639/Ti_639_TD_midplane.csv
[Measurement conditions]
Sample identification,
Comment - 1,"Configuration=Sample Spinner, Owner=User-1, Creation date=5/26/2011 3:50:48 PM"
Comment - 2,"Goniometer=PW3050/60 (Theta/Theta); Minimum step size 2Theta:0.001; Minimum step size Omega:0.001"
Comment - 3,"Sample stage=Spinner PW3064"
Comment - 4,"Diffractometer system=XPERT-PRO"
Comment - 5,"Measurement program=Ti_absolute, Owner=User-1, Creation date=8/11/2017 3:56:34 PM"
Anode material,Cu
K-Alpha1 wavelength,1.5405980
K-Alpha2 wavelength,1.5444260
Ratio K-Alpha2/K-Alpha1,0.500
Divergence slit,Fixed,0.5
Monochromator used,NO
Generator voltage, 45
Tube current, 40
File date and time,11/Aug/2017 16:25
Unit cell,
h k l, 0 0 0
Scan axis,Gonio
Scan range,29.996000003,124.999564637
Scan step size,0.0083556
No. of points, 11370
Scan type,CONTINUOUS
Time per step,19.685
[Scan points]
Angle,Intensity
30.000177820,51.0
30.067022896,62.0
30.133867973,46.0
30.200713049,48.0
30.267558125,62.0
30.334403201,54.0
30.401248278,48.0
30.468093354,64.0
30.534938430,60.0
30.601783506,60.0
30.668628583,53.0
30.735473659,48.0
30.802318735,51.0
30.869163811,72.0
30.936008888,47.0
31.002853964,55.0
31.069699040,47.0
31.136544116,48.0
31.203389193,42.0
31.270234269,51.0
31.337079345,59.0
31.403924421,47.0
31.470769498,51.0
31.537614574,53.0
31.604459650,52.0
31.671304727,42.0
31.738149803,56.0
31.804994879,49.0
31.871839955,45.0
31.938685032,49.0
32.005530108,43.0
32.072375184,57.0
32.139220260,60.0
32.206065337,45.0
32.272910413,55.0
32.339755489,41.0
32.406600565,53.0
32.473445642,41.0
32.540290718,37.0
32.607135794,46.0
32.673980870,49.0
32.740825947,46.0
32.807671023,39.0
32.874516099,45.0
32.941361175,47.0
33.008206252,51.0
33.075051328,31.0
33.141896404,54.0
33.208741480,46.0
33.275586557,49.0
33.342431633,36.0
33.409276709,53.0
33.476121786,41.0
33.542966862,48.0
33.609811938,61.0
33.676657014,44.0
33.743502091,52.0
33.810347167,47.0
33.877192243,47.0
33.944037319,54.0
34.010882396,43.0
34.077727472,43.0
34.144572548,54.0
34.211417624,44.0
34.278262701,52.0
34.345107777,52.0
34.411952853,39.0
34.478797929,57.0
34.545643006,37.0
34.612488082,52.0
34.679333158,39.0
34.746178234,60.0
34.813023311,44.0
34.879868387,57.0
34.946713463,46.0
35.013558540,55.0
35.080403616,75.0
35.147248692,56.0
35.214093768,44.0
35.280938845,57.0
35.347783921,53.0
35.414628997,75.0
35.481474073,65.0
35.548319150,92.0
35.615164226,99.0
35.682009302,183.0
35.748854378,282.0
35.815699455,720.0
35.882544531,1007.0
35.949389607,647.0
36.016234683,224.0
36.083079760,82.0
36.149924836,75.0
36.216769912,56.0
36.283614988,65.0
36.350460065,48.0
36.417305141,33.0
36.484150217,51.0
36.550995293,49.0
36.617840370,45.0
36.684685446,41.0
36.751530522,59.0
36.818375599,61.0
36.885220675,55.0
36.952065751,40.0
37.018910827,46.0
37.085755904,42.0
37.152600980,37.0
37.219446056,44.0
37.286291132,61.0
37.353136209,33.0
37.419981285,43.0
37.486826361,55.0
37.553671437,44.0
37.620516514,46.0
37.687361590,57.0
37.754206666,45.0
37.821051742,58.0
37.887896819,54.0
37.954741895,52.0
38.021586971,57.0
38.088432047,67.0
38.155277124,55.0
38.222122200,66.0
38.288967276,72.0
38.355812353,71.0
38.422657429,78.0
38.489502505,64.0
38.556347581,73.0
38.623192658,97.0
38.690037734,133.0
38.756882810,217.0
38.823727886,386.0
38.890572963,1191.0
38.957418039,2934.0
39.024263115,1517.0
39.091108191,722.0
39.157953268,197.0
39.224798344,149.0
39.291643420,90.0
39.358488496,84.0
39.425333573,99.0
39.492178649,122.0
39.559023725,157.0
39.625868801,237.0
39.692713878,403.0
39.759558954,544.0
39.826404030,429.0
39.893249106,327.0
39.960094183,167.0
40.026939259,119.0
40.093784335,93.0
40.160629412,88.0
40.227474488,68.0
40.294319564,86.0
40.361164640,91.0
40.428009717,95.0
40.494854793,119.0
40.561699869,135.0
40.628544945,232.0
40.695390022,349.0
40.762235098,530.0
40.829080174,1129.0
40.895925250,2819.0
40.962770327,2157.0
41.029615403,1543.0
41.096460479,475.0
41.163305555,181.0
41.230150632,118.0
41.296995708,73.0
41.363840784,71.0
41.430685860,59.0
41.497530937,54.0
41.564376013,52.0
41.631221089,53.0
41.698066166,47.0
41.764911242,52.0
41.831756318,56.0
41.898601394,59.0
41.965446471,44.0
42.032291547,52.0
42.099136623,52.0
42.165981699,33.0
42.232826776,37.0
42.299671852,48.0
42.366516928,51.0
42.433362004,43.0
42.500207081,33.0
42.567052157,44.0
42.633897233,40.0
42.700742309,53.0
42.767587386,41.0
42.834432462,42.0
42.901277538,52.0
42.968122614,33.0
43.034967691,40.0
43.101812767,41.0
43.168657843,35.0
43.235502919,33.0
43.302347996,31.0
43.369193072,45.0
43.436038148,36.0
43.502883225,35.0
43.569728301,35.0
43.636573377,37.0
43.703418453,30.0
43.770263530,33.0
43.837108606,33.0
43.903953682,26.0
43.970798758,29.0
44.037643835,37.0
44.104488911,31.0
44.171333987,37.0
44.238179063,32.0
44.305024140,36.0
44.371869216,36.0
44.438714292,37.0
44.505559368,54.0
44.572404445,37.0
44.639249521,30.0
44.706094597,32.0
44.772939673,33.0
44.839784750,27.0
44.906629826,29.0
44.973474902,33.0
45.040319979,24.0
45.107165055,21.0
45.174010131,37.0
45.240855207,33.0
45.307700284,34.0
45.374545360,35.0
45.441390436,30.0
45.508235512,31.0
45.575080589,27.0
45.641925665,33.0
45.708770741,30.0
45.775615817,34.0
45.842460894,23.0
45.909305970,33.0
45.976151046,26.0
46.042996122,29.0
46.109841199,24.0
46.176686275,14.0
46.243531351,34.0
46.310376427,26.0
46.377221504,27.0
46.444066580,26.0
46.510911656,26.0
46.577756732,39.0
46.644601809,16.0
46.711446885,19.0
46.778291961,19.0
46.845137038,24.0
46.911982114,23.0
46.978827190,34.0
47.045672266,27.0
47.112517343,30.0
47.179362419,22.0
47.246207495,26.0
47.313052571,26.0
47.379897648,27.0
47.446742724,36.0
47.513587800,21.0
47.580432876,28.0
47.647277953,32.0
47.714123029,27.0
47.780968105,23.0
47.847813181,33.0
47.914658258,15.0
47.981503334,32.0
48.048348410,32.0
48.115193486,27.0
48.182038563,24.0
48.248883639,37.0
48.315728715,26.0
48.382573792,31.0
48.449418868,17.0
48.516263944,22.0
48.583109020,21.0
48.649954097,27.0
48.716799173,28.0
48.783644249,30.0
48.850489325,27.0
48.917334402,29.0
48.984179478,30.0
49.051024554,22.0
49.117869630,29.0
49.184714707,24.0
49.251559783,26.0
49.318404859,30.0
49.385249935,20.0
49.452095012,17.0
49.518940088,24.0
49.585785164,29.0
49.652630240,29.0
49.719475317,18.0
49.786320393,21.0
49.853165469,21.0
49.920010545,16.0
49.986855622,28.0
50.053700698,17.0
50.120545774,22.0
50.187390851,20.0
50.254235927,27.0
50.321081003,24.0
50.387926079,23.0
50.454771156,27.0
50.521616232,27.0
50.588461308,23.0
50.655306384,26.0
50.722151461,24.0
50.788996537,23.0
50.855841613,27.0
50.922686689,15.0
50.989531766,20.0
51.056376842,20.0
51.123221918,24.0
51.190066994,24.0
51.256912071,19.0
51.323757147,24.0
51.390602223,33.0
51.457447299,23.0
51.524292376,18.0
51.591137452,28.0
51.657982528,22.0
51.724827605,29.0
51.791672681,23.0
51.858517757,19.0
51.925362833,31.0
51.992207910,19.0
52.059052986,23.0
52.125898062,31.0
52.192743138,43.0
52.259588215,33.0
52.326433291,27.0
52.393278367,19.0
52.460123443,28.0
52.526968520,23.0
52.593813596,21.0
52.660658672,18.0
52.727503748,28.0
52.794348825,23.0
52.861193901,26.0
52.928038977,23.0
52.994884053,19.0
53.061729130,30.0
53.128574206,23.0
53.195419282,33.0
53.262264358,34.0
53.329109435,32.0
53.395954511,30.0
53.462799587,45.0
53.529644664,55.0
53.596489740,99.0
53.663334816,230.0
53.730179892,381.0
53.797024969,194.0
53.863870045,227.0
53.930715121,100.0
53.997560197,42.0
54.064405274,49.0
54.131250350,35.0
54.198095426,22.0
54.264940502,19.0
54.331785579,20.0
54.398630655,27.0
54.465475731,22.0
54.532320807,11.0
54.599165884,28.0
54.666010960,23.0
54.732856036,13.0
54.799701112,22.0
54.866546189,24.0
54.933391265,21.0
55.000236341,22.0
55.067081418,26.0
55.133926494,27.0
55.200771570,20.0
55.267616646,19.0
55.334461723,23.0
55.401306799,22.0
55.468151875,23.0
55.534996951,24.0
55.601842028,20.0
55.668687104,16.0
55.735532180,29.0
55.802377256,19.0
55.869222333,28.0
55.936067409,20.0
56.002912485,16.0
56.069757561,29.0
56.136602638,17.0
56.203447714,29.0
56.270292790,23.0
56.337137866,19.0
56.403982943,26.0
56.470828019,20.0
56.537673095,19.0
56.604518171,21.0
56.671363248,23.0
56.738208324,27.0
56.805053400,28.0
56.871898477,28.0
56.938743553,29.0
57.005588629,39.0
57.072433705,27.0
57.139278782,48.0
57.206123858,39.0
57.272968934,60.0
57.339814010,69.0
57.406659087,49.0
57.473504163,36.0
57.540349239,39.0
57.607194315,29.0
57.674039392,28.0
57.740884468,27.0
57.807729544,22.0
57.874574620,26.0
57.941419697,17.0
58.008264773,22.0
58.075109849,15.0
58.141954925,17.0
58.208800002,14.0
58.275645078,21.0
58.342490154,15.0
58.409335231,18.0
58.476180307,14.0
58.543025383,26.0
58.609870459,20.0
58.676715536,13.0
58.743560612,24.0
58.810405688,20.0
58.877250764,16.0
58.944095841,14.0
59.010940917,16.0
59.077785993,20.0
59.144631069,9.0
59.211476146,11.0
59.278321222,21.0
59.345166298,15.0
59.412011374,24.0
59.478856451,20.0
59.545701527,23.0
59.612546603,18.0
59.679391679,17.0
59.746236756,23.0
59.813081832,17.0
59.879926908,14.0
59.946771984,13.0
60.013617061,17.0
60.080462137,22.0
60.147307213,18.0
60.214152290,23.0
60.280997366,15.0
60.347842442,15.0
60.414687518,18.0
60.481532595,19.0
60.548377671,27.0
60.615222747,18.0
60.682067823,28.0
60.748912900,19.0
60.815757976,23.0
60.882603052,15.0
60.949448128,21.0
61.016293205,26.0
61.083138281,16.0
61.149983357,23.0
61.216828433,20.0
61.283673510,17.0
61.350518586,21.0
61.417363662,18.0
61.484208738,15.0
61.551053815,21.0
61.617898891,24.0
61.684743967,17.0
61.751589044,19.0
61.818434120,23.0
61.885279196,17.0
61.952124272,21.0
62.018969349,16.0
62.085814425,16.0
62.152659501,11.0
62.219504577,19.0
62.286349654,11.0
62.353194730,26.0
62.420039806,18.0
62.486884882,29.0
62.553729959,18.0
62.620575035,21.0
62.687420111,17.0
62.754265187,23.0
62.821110264,28.0
62.887955340,16.0
62.954800416,21.0
63.021645492,17.0
63.088490569,19.0
63.155335645,24.0
63.222180721,30.0
63.289025797,17.0
63.355870874,19.0
63.422715950,29.0
63.489561026,16.0
63.556406103,31.0
63.623251179,33.0
63.690096255,36.0
63.756941331,34.0
63.823786408,43.0
63.890631484,91.0
63.957476560,169.0
64.024321636,109.0
64.091166713,93.0
64.158011789,93.0
64.224856865,64.0
64.291701941,29.0
64.358547018,27.0
64.425392094,13.0
64.492237170,20.0
64.559082246,13.0
64.625927323,14.0
64.692772399,16.0
64.759617475,11.0
64.826462551,27.0
64.893307628,21.0
64.960152704,19.0
65.026997780,20.0
65.093842857,17.0
65.160687933,20.0
65.227533009,15.0
65.294378085,19.0
65.361223162,21.0
65.428068238,13.0
65.494913314,20.0
65.561758390,19.0
65.628603467,11.0
65.695448543,16.0
65.762293619,17.0
65.829138695,20.0
65.895983772,21.0
65.962828848,18.0
66.029673924,14.0
66.096519000,20.0
66.163364077,16.0
66.230209153,18.0
66.297054229,20.0
66.363899305,17.0
66.430744382,9.0
66.497589458,19.0
66.564434534,10.0
66.631279610,20.0
66.698124687,17.0
66.764969763,23.0
66.831814839,13.0
66.898659916,11.0
66.965504992,20.0
67.032350068,16.0
67.099195144,17.0
67.166040221,18.0
67.232885297,26.0
67.299730373,17.0
67.366575449,17.0
67.433420526,14.0
67.500265602,13.0
67.567110678,18.0
67.633955754,14.0
67.700800831,8.0
67.767645907,22.0
67.834490983,18.0
67.901336059,17.0
67.968181136,19.0
68.035026212,15.0
68.101871288,15.0
68.168716364,24.0
68.235561441,23.0
68.302406517,14.0
68.369251593,18.0
68.436096670,17.0
68.502941746,23.0
68.569786822,17.0
68.636631898,20.0
68.703476975,13.0
68.770322051,23.0
68.837167127,22.0
68.904012203,18.0
68.970857280,27.0
69.037702356,14.0
69.104547432,29.0
69.171392508,18.0
69.238237585,23.0
69.305082661,22.0
69.371927737,24.0
69.438772813,19.0
69.505617890,22.0
69.572462966,19.0
69.639308042,21.0
69.706153118,16.0
69.772998195,18.0
69.839843271,20.0
69.906688347,18.0
69.973533423,30.0
70.040378500,16.0
70.107223576,20.0
70.174068652,18.0
70.240913729,18.0
70.307758805,24.0
70.374603881,17.0
70.441448957,20.0
70.508294034,15.0
70.575139110,18.0
70.641984186,15.0
70.708829262,21.0
70.775674339,23.0
70.842519415,26.0
70.909364491,22.0
70.976209567,40.0
71.043054644,51.0
71.109899720,43.0
71.176744796,61.0
71.243589872,113.0
71.310434949,211.0
71.377280025,388.0
71.444125101,222.0
71.510970177,209.0
71.577815254,264.0
71.644660330,156.0
71.711505406,109.0
71.778350483,66.0
71.845195559,47.0
71.912040635,55.0
71.978885711,36.0
72.045730788,35.0
72.112575864,24.0
72.179420940,26.0
72.246266016,28.0
72.313111093,23.0
72.379956169,15.0
72.446801245,22.0
72.513646321,17.0
72.580491398,29.0
72.647336474,23.0
72.714181550,21.0
72.781026626,14.0
72.847871703,20.0
72.914716779,19.0
72.981561855,22.0
73.048406931,20.0
73.115252008,24.0
73.182097084,18.0
73.248942160,32.0
73.315787236,11.0
73.382632313,17.0
73.449477389,15.0
73.516322465,10.0
73.583167542,17.0
73.650012618,15.0
73.716857694,14.0
73.783702770,20.0
73.850547847,30.0
73.917392923,22.0
73.984237999,15.0
74.051083075,18.0
74.117928152,26.0
74.184773228,14.0
74.251618304,19.0
74.318463380,16.0
74.385308457,28.0
74.452153533,20.0
74.518998609,19.0
74.585843685,23.0
74.652688762,22.0
74.719533838,17.0
74.786378914,14.0
74.853223990,16.0
74.920069067,18.0
74.986914143,23.0
75.053759219,17.0
75.120604296,15.0
75.187449372,26.0
75.254294448,56.0
75.321139524,58.0
75.387984601,44.0
75.454829677,35.0
75.521674753,49.0
75.588519829,30.0
75.655364906,21.0
75.722209982,21.0
75.789055058,9.0
75.855900134,22.0
75.922745211,15.0
75.989590287,19.0
76.056435363,20.0
76.123280439,19.0
76.190125516,17.0
76.256970592,17.0
76.323815668,28.0
76.390660744,15.0
76.457505821,18.0
76.524350897,24.0
76.591195973,23.0
76.658041049,18.0
76.724886126,31.0
76.791731202,20.0
76.858576278,30.0
76.925421355,36.0
76.992266431,34.0
77.059111507,75.0
77.125956583,116.0
77.192801660,206.0
77.259646736,182.0
77.326491812,125.0
77.393336888,117.0
77.460181965,128.0
77.527027041,81.0
77.593872117,48.0
77.660717193,35.0
77.727562270,28.0
77.794407346,16.0
77.861252422,27.0
77.928097498,18.0
77.994942575,26.0
78.061787651,34.0
78.128632727,34.0
78.195477803,37.0
78.262322880,54.0
78.329167956,57.0
78.396013032,90.0
78.462858109,176.0
78.529703185,222.0
78.596548261,159.0
78.663393337,104.0
78.730238414,112.0
78.797083490,95.0
78.863928566,53.0
78.930773642,32.0
78.997618719,26.0
79.064463795,18.0
79.131308871,22.0
79.198153947,19.0
79.264999024,9.0
79.331844100,23.0
79.398689176,18.0
79.465534252,20.0
79.532379329,19.0
79.599224405,18.0
79.666069481,15.0
79.732914557,22.0
79.799759634,20.0
79.866604710,22.0
79.933449786,8.0
80.000294862,22.0
80.067139939,11.0
80.133985015,15.0
80.200830091,20.0
80.267675168,11.0
80.334520244,20.0
80.401365320,13.0
80.468210396,11.0
80.535055473,21.0
80.601900549,30.0
80.668745625,16.0
80.735590701,13.0
80.802435778,19.0
80.869280854,19.0
80.936125930,18.0
81.002971006,22.0
81.069816083,8.0
81.136661159,15.0
81.203506235,10.0
81.270351311,14.0
81.337196388,11.0
81.404041464,20.0
81.470886540,16.0
81.537731616,14.0
81.604576693,22.0
81.671421769,13.0
81.738266845,19.0
81.805111922,15.0
81.871956998,18.0
81.938802074,21.0
82.005647150,10.0
82.072492227,23.0
82.139337303,16.0
82.206182379,20.0
82.273027455,15.0
82.339872532,19.0
82.406717608,15.0
82.473562684,26.0
82.540407760,20.0
82.607252837,16.0
82.674097913,22.0
82.740942989,24.0
82.807788065,65.0
82.874633142,117.0
82.941478218,123.0
83.008323294,51.0
83.075168370,49.0
83.142013447,52.0
83.208858523,49.0
83.275703599,27.0
83.342548675,17.0
83.409393752,19.0
83.476238828,14.0
83.543083904,11.0
83.609928981,16.0
83.676774057,18.0
83.743619133,13.0
83.810464209,22.0
83.877309286,22.0
83.944154362,14.0
84.010999438,19.0
84.077844514,16.0
84.144689591,17.0
84.211534667,8.0
84.278379743,17.0
84.345224819,19.0
84.412069896,22.0
84.478914972,20.0
84.545760048,15.0
84.612605124,19.0
84.679450201,19.0
84.746295277,16.0
84.813140353,19.0
84.879985429,26.0
84.946830506,18.0
85.013675582,21.0
85.080520658,21.0
85.147365735,24.0
85.214210811,30.0
85.281055887,27.0
85.347900963,17.0
85.414746040,20.0
85.481591116,19.0
85.548436192,18.0
85.615281268,14.0
85.682126345,19.0
85.748971421,15.0
85.815816497,20.0
85.882661573,23.0
85.949506650,14.0
86.016351726,13.0
86.083196802,11.0
86.150041878,18.0
86.216886955,14.0
86.283732031,20.0
86.350577107,20.0
86.417422183,19.0
86.484267260,17.0
86.551112336,17.0
86.617957412,17.0
86.684802488,16.0
86.751647565,21.0
86.818492641,20.0
86.885337717,16.0
86.952182794,15.0
87.019027870,13.0
87.085872946,20.0
87.152718022,22.0
87.219563099,16.0
87.286408175,16.0
87.353253251,18.0
87.420098327,11.0
87.486943404,20.0
87.553788480,6.0
87.620633556,17.0
87.687478632,10.0
87.754323709,34.0
87.821168785,24.0
87.888013861,48.0
87.954858937,53.0
88.021704014,42.0
88.088549090,30.0
88.155394166,32.0
88.222239242,37.0
88.289084319,27.0
88.355929395,22.0
88.422774471,16.0
88.489619548,9.0
88.556464624,20.0
88.623309700,17.0
88.690154776,9.0
88.756999853,18.0
88.823844929,9.0
88.890690005,20.0
88.957535081,14.0
89.024380158,8.0
89.091225234,14.0
89.158070310,9.0
89.224915386,18.0
89.291760463,16.0
89.358605539,11.0
89.425450615,19.0
89.492295691,14.0
89.559140768,14.0
89.625985844,10.0
89.692830920,17.0
89.759675996,15.0
89.826521073,22.0
89.893366149,21.0
89.960211225,15.0
90.027056301,17.0
90.093901378,9.0
90.160746454,10.0
90.227591530,10.0
90.294436607,21.0
90.361281683,18.0
90.428126759,10.0
90.494971835,13.0
90.561816912,15.0
90.628661988,10.0
90.695507064,8.0
90.762352140,14.0
90.829197217,16.0
90.896042293,11.0
90.962887369,18.0
91.029732445,8.0
91.096577522,13.0
91.163422598,19.0
91.230267674,10.0
91.297112750,22.0
91.363957827,9.0
91.430802903,14.0
91.497647979,10.0
91.564493055,16.0
91.631338132,14.0
91.698183208,9.0
91.765028284,14.0
91.831873361,20.0
91.898718437,11.0
91.965563513,6.0
92.032408589,19.0
92.099253666,14.0
92.166098742,13.0
92.232943818,13.0
92.299788894,16.0
92.366633971,7.0
92.433479047,9.0
92.500324123,11.0
92.567169199,15.0
92.634014276,19.0
92.700859352,8.0
92.767704428,19.0
92.834549504,13.0
92.901394581,11.0
92.968239657,18.0
93.035084733,10.0
93.101929809,15.0
93.168774886,20.0
93.235619962,19.0
93.302465038,23.0
93.369310114,43.0
93.436155191,48.0
93.503000267,85.0
93.569845343,52.0
93.636690420,32.0
93.703535496,22.0
93.770380572,41.0
93.837225648,35.0
93.904070725,22.0
93.970915801,19.0
94.037760877,18.0
94.104605953,15.0
94.171451030,15.0
94.238296106,17.0
94.305141182,13.0
94.371986258,19.0
94.438831335,10.0
94.505676411,18.0
94.572521487,10.0
94.639366563,9.0
94.706211640,19.0
94.773056716,15.0
94.839901792,17.0
94.906746868,15.0
94.973591945,10.0
95.040437021,13.0
95.107282097,10.0
95.174127174,7.0
95.240972250,21.0
95.307817326,8.0
95.374662402,18.0
95.441507479,9.0
95.508352555,16.0
95.575197631,20.0
95.642042707,13.0
95.708887784,14.0
95.775732860,11.0
95.842577936,18.0
95.909423012,8.0
95.976268089,15.0
96.043113165,8.0
96.109958241,19.0
96.176803317,19.0
96.243648394,6.0
96.310493470,13.0
96.377338546,13.0
96.444183622,24.0
96.511028699,16.0
96.577873775,10.0
96.644718851,17.0
96.711563927,16.0
96.778409004,10.0
96.845254080,8.0
96.912099156,19.0
96.978944233,9.0
97.045789309,14.0
97.112634385,15.0
97.179479461,9.0
97.246324538,14.0
97.313169614,20.0
97.380014690,11.0
97.446859766,20.0
97.513704843,21.0
97.580549919,16.0
97.647394995,14.0
97.714240071,15.0
97.781085148,21.0
97.847930224,20.0
97.914775300,17.0
97.981620376,28.0
98.048465453,27.0
98.115310529,21.0
98.182155605,19.0
98.249000681,20.0
98.315845758,18.0
98.382690834,16.0
98.449535910,22.0
98.516380987,15.0
98.583226063,9.0
98.650071139,14.0
98.716916215,10.0
98.783761292,9.0
98.850606368,8.0
98.917451444,17.0
98.984296520,15.0
99.051141597,10.0
99.117986673,14.0
99.184831749,14.0
99.251676825,11.0
99.318521902,20.0
99.385366978,13.0
99.452212054,21.0
99.519057130,11.0
99.585902207,16.0
99.652747283,15.0
99.719592359,19.0
99.786437435,15.0
99.853282512,19.0
99.920127588,16.0
99.986972664,17.0
100.053817740,20.0
100.120662817,14.0
100.187507893,16.0
100.254352969,23.0
100.321198046,7.0
100.388043122,7.0
100.454888198,10.0
100.521733274,8.0
100.588578351,18.0
100.655423427,11.0
100.722268503,14.0
100.789113579,19.0
100.855958656,10.0
100.922803732,13.0
100.989648808,13.0
101.056493884,13.0
101.123338961,6.0
101.190184037,9.0
101.257029113,17.0
101.323874189,8.0
101.390719266,16.0
101.457564342,22.0
101.524409418,13.0
101.591254494,15.0
101.658099571,7.0
101.724944647,13.0
101.791789723,10.0
101.858634800,10.0
101.925479876,19.0
101.992324952,23.0
102.059170028,10.0
102.126015105,16.0
102.192860181,13.0
102.259705257,16.0
102.326550333,17.0
102.393395410,14.0
102.460240486,17.0
102.527085562,18.0
102.593930638,17.0
102.660775715,13.0
102.727620791,11.0
102.794465867,22.0
102.861310943,16.0
102.928156020,9.0
102.995001096,18.0
103.061846172,16.0
103.128691248,9.0
103.195536325,34.0
103.262381401,23.0
103.329226477,33.0
103.396071553,24.0
103.462916630,47.0
103.529761706,64.0
103.596606782,99.0
103.663451859,56.0
103.730296935,41.0
103.797142011,29.0
103.863987087,42.0
103.930832164,47.0
103.997677240,37.0
104.064522316,42.0
104.131367392,16.0
104.198212469,15.0
104.265057545,15.0
104.331902621,8.0
104.398747697,15.0
104.465592774,17.0
104.532437850,14.0
104.599282926,22.0
104.666128002,17.0
104.732973079,13.0
104.799818155,16.0
104.866663231,26.0
104.933508307,14.0
105.000353384,13.0
105.067198460,9.0
105.134043536,16.0
105.200888613,19.0
105.267733689,10.0
105.334578765,14.0
105.401423841,21.0
105.468268918,15.0
105.535113994,13.0
105.601959070,27.0
105.668804146,9.0
105.735649223,15.0
105.802494299,17.0
105.869339375,16.0
105.936184451,20.0
106.003029528,18.0
106.069874604,21.0
106.136719680,17.0
106.203564756,15.0
106.270409833,13.0
106.337254909,18.0
106.404099985,10.0
106.470945061,19.0
106.537790138,17.0
106.604635214,11.0
106.671480290,18.0
106.738325366,9.0
106.805170443,10.0
106.872015519,11.0
106.938860595,8.0
107.005705672,22.0
107.072550748,14.0
107.139395824,20.0
107.206240900,19.0
107.273085977,18.0
107.339931053,29.0
107.406776129,34.0
107.473621205,22.0
107.540466282,31.0
107.607311358,26.0
107.674156434,19.0
107.741001510,22.0
107.807846587,23.0
107.874691663,28.0
107.941536739,13.0
108.008381815,14.0
108.075226892,13.0
108.142071968,14.0
108.208917044,15.0
108.275762120,8.0
108.342607197,19.0
108.409452273,14.0
108.476297349,15.0
108.543142426,13.0
108.609987502,13.0
108.676832578,11.0
108.743677654,20.0
108.810522731,18.0
108.877367807,16.0
108.944212883,16.0
109.011057959,18.0
109.077903036,13.0
109.144748112,18.0
109.211593188,22.0
109.278438264,32.0
109.345283341,13.0
109.412128417,18.0
109.478973493,13.0
109.545818569,16.0
109.612663646,15.0
109.679508722,14.0
109.746353798,23.0
109.813198874,14.0
109.880043951,19.0
109.946889027,23.0
110.013734103,19.0
110.080579179,16.0
110.147424256,18.0
110.214269332,22.0
110.281114408,27.0
110.347959485,19.0
110.414804561,18.0
110.481649637,30.0
110.548494713,39.0
110.615339790,45.0
110.682184866,75.0
110.749029942,79.0
110.815875018,99.0
110.882720095,64.0
110.949565171,34.0
111.016410247,59.0
111.083255323,51.0
111.150100400,42.0
111.216945476,45.0
111.283790552,46.0
111.350635628,27.0
111.417480705,30.0
111.484325781,22.0
111.551170857,21.0
111.618015933,15.0
111.684861010,27.0
111.751706086,11.0
111.818551162,23.0
111.885396239,14.0
111.952241315,20.0
112.019086391,13.0
112.085931467,16.0
112.152776544,8.0
112.219621620,19.0
112.286466696,16.0
112.353311772,19.0
112.420156849,21.0
112.487001925,16.0
112.553847001,17.0
112.620692077,14.0
112.687537154,22.0
112.754382230,20.0
112.821227306,24.0
112.888072382,20.0
112.954917459,13.0
113.021762535,21.0
113.088607611,17.0
113.155452687,16.0
113.222297764,15.0
113.289142840,19.0
113.355987916,18.0
113.422832992,22.0
113.489678069,27.0
113.556523145,24.0
113.623368221,17.0
113.690213298,16.0
113.757058374,6.0
113.823903450,15.0
113.890748526,18.0
113.957593603,16.0
114.024438679,17.0
114.091283755,14.0
114.158128831,13.0
114.224973908,13.0
114.291818984,8.0
114.358664060,19.0
114.425509136,19.0
114.492354213,19.0
114.559199289,19.0
114.626044365,23.0
114.692889441,9.0
114.759734518,21.0
114.826579594,18.0
114.893424670,16.0
114.960269746,17.0
115.027114823,24.0
115.093959899,28.0
115.160804975,26.0
115.227650052,36.0
115.294495128,66.0
115.361340204,92.0
115.428185280,112.0
115.495030357,91.0
115.561875433,48.0
115.628720509,58.0
115.695565585,57.0
115.762410662,49.0
115.829255738,54.0
115.896100814,61.0
115.962945890,47.0
116.029790967,28.0
116.096636043,41.0
116.163481119,29.0
116.230326195,22.0
116.297171272,17.0
116.364016348,15.0
116.430861424,19.0
116.497706500,20.0
116.564551577,18.0
116.631396653,22.0
116.698241729,17.0
116.765086805,10.0
116.831931882,10.0
116.898776958,18.0
116.965622034,17.0
117.032467111,14.0
117.099312187,14.0
117.166157263,10.0
117.233002339,9.0
117.299847416,10.0
117.366692492,19.0
117.433537568,19.0
117.500382644,28.0
117.567227721,19.0
117.634072797,22.0
117.700917873,21.0
117.767762949,16.0
117.834608026,13.0
117.901453102,18.0
117.968298178,16.0
118.035143254,18.0
118.101988331,13.0
118.168833407,21.0
118.235678483,15.0
118.302523559,21.0
118.369368636,15.0
118.436213712,11.0
118.503058788,24.0
118.569903865,18.0
118.636748941,17.0
118.703594017,18.0
118.770439093,21.0
118.837284170,15.0
118.904129246,14.0
118.970974322,17.0
119.037819398,16.0
119.104664475,20.0
119.171509551,10.0
119.238354627,16.0
119.305199703,22.0
119.372044780,15.0
119.438889856,19.0
119.505734932,7.0
119.572580008,15.0
119.639425085,15.0
119.706270161,14.0
119.773115237,19.0
119.839960313,20.0
119.906805390,14.0
119.973650466,16.0
120.040495542,11.0
120.107340618,11.0
120.174185695,20.0
120.241030771,23.0
120.307875847,21.0
120.374720924,26.0
120.441566000,18.0
120.508411076,22.0
120.575256152,20.0
120.642101229,22.0
120.708946305,27.0
120.775791381,20.0
120.842636457,18.0
120.909481534,28.0
120.976326610,26.0
121.043171686,43.0
121.110016762,44.0
121.176861839,48.0
121.243706915,34.0
121.310551991,34.0
121.377397067,27.0
121.444242144,22.0
121.511087220,26.0
121.577932296,24.0
121.644777372,29.0
121.711622449,27.0
121.778467525,22.0
121.845312601,22.0
121.912157678,19.0
121.979002754,19.0
122.045847830,29.0
122.112692906,16.0
122.179537983,18.0
122.246383059,21.0
122.313228135,10.0
122.380073211,17.0
122.446918288,18.0
122.513763364,21.0
122.580608440,17.0
122.647453516,21.0
122.714298593,17.0
122.781143669,15.0
122.847988745,31.0
122.914833821,26.0
122.981678898,41.0
123.048523974,64.0
123.115369050,75.0
123.182214126,142.0
123.249059203,115.0
123.315904279,88.0
123.382749355,64.0
123.449594431,46.0
123.516439508,48.0
123.583284584,52.0
123.650129660,39.0
123.716974737,58.0
123.783819813,86.0
123.850664889,68.0
123.917509965,33.0
123.984355042,29.0
124.051200118,18.0
124.118045194,37.0
124.184890270,22.0
124.251735347,21.0
124.318580423,20.0
124.385425499,15.0
124.452270575,23.0
124.519115652,15.0
124.585960728,16.0
124.652805804,18.0
124.719650880,20.0
124.786495957,23.0
124.853341033,13.0
124.920186109,23.0
124.987031185,18.0
124.995386820,11.0