File: Data/ARL/Fulin/Timet-18/Texture/47_bkgd.xrdml
<?xml version="1.0" encoding="UTF-8"?>
<xrdMeasurements xmlns="http://www.xrdml.com/XRDMeasurement/1.5" xmlns:xsi="http://www.w3.org/2001/XMLSchema-instance" xsi:schemaLocation="http://www.xrdml.com/XRDMeasurement/1.5 http://www.xrdml.com/XRDMeasurement/1.5/XRDMeasurement.xsd" status="Completed">
	<comment>
		<entry>Configuration=Open Eulerian Cradle (manual Z), Owner=User-1, Creation date=4/3/2012 1:39:10 PM</entry>
		<entry>Goniometer=PW3050/60 (Theta/Theta); Minimum step size 2Theta:0.001; Minimum step size Omega:0.001</entry>
		<entry>Sample stage=Open Eulerian Cradle (manual Z); Minimum step size Phi:0.01; Minimum step size Chi:0.01</entry>
		<entry>Diffractometer system=XPERT-PRO</entry>
		<entry>Measurement program=RP12L_bkgd, Owner=User-1, Creation date=8/20/2012 10:01:24 PM</entry>
		<entry>Batch program=Titanium_texture, Owner=User-1, Creation date=8/14/2017 7:26:15 PM</entry>
	</comment>
	<sample type="To be analyzed">
		<id></id>
		<name></name>
		<preparedBy></preparedBy>
	</sample>
	<xrdMeasurement measurementType="Texture background measurement" status="Completed" measurementStepAxis="Chi" sampleMode="Reflection">
		<comment>
			<entry>340C</entry>
		</comment>
		<usedWavelength intended="K-Alpha">
			<kAlpha1 unit="Angstrom">1.5405980</kAlpha1>
			<kAlpha2 unit="Angstrom">1.5444260</kAlpha2>
			<kBeta unit="Angstrom">1.3922500</kBeta>
			<ratioKAlpha2KAlpha1>0.5000</ratioKAlpha2KAlpha1>
		</usedWavelength>
		<incidentBeamPath>
			<radius unit="mm">240.00</radius>
			<xRayTube id="1010048" name="Empyrean XRD tube Cu LFF HR DK302959">
				<tension unit="kV">45</tension>
				<current unit="mA">40</current>
				<anodeMaterial>Cu</anodeMaterial>
				<focus type="Point">
					<length unit="mm">12.0</length>
					<width unit="mm">0.4</width>
					<takeOffAngle unit="deg">6.0</takeOffAngle>
				</focus>
			</xRayTube>
			<mask id="22030009" name="Fixed mask 10 mm">
				<width unit="mm">10.00</width>
			</mask>
		</incidentBeamPath>
		<diffractedBeamPath>
			<radius unit="mm">240.00</radius>
			<sollerSlit id="21010002" name="Soller slits 0.04 rad.">
				<opening unit="rad">0.0400</opening>
			</sollerSlit>
			<parallelPlateCollimator id="25010002" name="Parallel plate collimator 0.18Â°">
				<opening unit="deg">0.18</opening>
			</parallelPlateCollimator>
			<receivingSlit id="22070001" name="Parallel plate collimator slit">
				<height unit="mm">0.10</height>
			</receivingSlit>
			<detector id="7010011" name="Proportional detector Xe" xsi:type="pointDetectorType">
				<phd>
					<lowerLevel unit="%">30.0</lowerLevel>
					<upperLevel unit="%">80.0</upperLevel>
				</phd>
			</detector>
		</diffractedBeamPath>
		<scan appendNumber="0" mode="Pre-set time" scanAxis="Phi" status="Completed">
			<header>
				<startTimeStamp>2017-08-15T02:07:56-04:00</startTimeStamp>
				<endTimeStamp>2017-08-15T02:08:05-04:00</endTimeStamp>
				<author>
					<name>ms5c</name>
				</author>
				<source>
					<applicationSoftware version="3.0c">Data Collector</applicationSoftware>
					<instrumentControlSoftware version="2.1A">XPERT-PRO</instrumentControlSoftware>
					<instrumentID>0000000014024241</instrumentID>
				</source>
			</header>
			<dataPoints>
				<positions axis="2Theta" unit="deg">
					<commonPosition>47.000</commonPosition>
				</positions>
				<positions axis="Omega" unit="deg">
					<commonPosition>23.500</commonPosition>
				</positions>
				<positions axis="Phi" unit="deg">
					<startPosition>0.00</startPosition>
					<endPosition>0.00</endPosition>
				</positions>
				<positions axis="Chi" unit="deg">
					<commonPosition>0.00</commonPosition>
				</positions>
				<commonCountingTime unit="seconds">2.00</commonCountingTime>
				<intensities unit="counts">2159</intensities>
			</dataPoints>
		</scan>
		<scan appendNumber="0" mode="Pre-set time" scanAxis="Phi" status="Completed">
			<header>
				<startTimeStamp>2017-08-15T02:08:14-04:00</startTimeStamp>
				<endTimeStamp>2017-08-15T02:08:17-04:00</endTimeStamp>
				<author>
					<name>ms5c</name>
				</author>
				<source>
					<applicationSoftware version="3.0c">Data Collector</applicationSoftware>
					<instrumentControlSoftware version="2.1A">XPERT-PRO</instrumentControlSoftware>
					<instrumentID>0000000014024241</instrumentID>
				</source>
			</header>
			<dataPoints>
				<positions axis="2Theta" unit="deg">
					<commonPosition>47.000</commonPosition>
				</positions>
				<positions axis="Omega" unit="deg">
					<commonPosition>23.500</commonPosition>
				</positions>
				<positions axis="Phi" unit="deg">
					<startPosition>0.00</startPosition>
					<endPosition>0.00</endPosition>
				</positions>
				<positions axis="Chi" unit="deg">
					<commonPosition>5.00</commonPosition>
				</positions>
				<commonCountingTime unit="seconds">2.00</commonCountingTime>
				<intensities unit="counts">2090</intensities>
			</dataPoints>
		</scan>
		<scan appendNumber="0" mode="Pre-set time" scanAxis="Phi" status="Completed">
			<header>
				<startTimeStamp>2017-08-15T02:08:25-04:00</startTimeStamp>
				<endTimeStamp>2017-08-15T02:08:28-04:00</endTimeStamp>
				<author>
					<name>ms5c</name>
				</author>
				<source>
					<applicationSoftware version="3.0c">Data Collector</applicationSoftware>
					<instrumentControlSoftware version="2.1A">XPERT-PRO</instrumentControlSoftware>
					<instrumentID>0000000014024241</instrumentID>
				</source>
			</header>
			<dataPoints>
				<positions axis="2Theta" unit="deg">
					<commonPosition>47.000</commonPosition>
				</positions>
				<positions axis="Omega" unit="deg">
					<commonPosition>23.500</commonPosition>
				</positions>
				<positions axis="Phi" unit="deg">
					<startPosition>0.00</startPosition>
					<endPosition>0.00</endPosition>
				</positions>
				<positions axis="Chi" unit="deg">
					<commonPosition>10.00</commonPosition>
				</positions>
				<commonCountingTime unit="seconds">2.00</commonCountingTime>
				<intensities unit="counts">2115</intensities>
			</dataPoints>
		</scan>
		<scan appendNumber="0" mode="Pre-set time" scanAxis="Phi" status="Completed">
			<header>
				<startTimeStamp>2017-08-15T02:08:36-04:00</startTimeStamp>
				<endTimeStamp>2017-08-15T02:08:39-04:00</endTimeStamp>
				<author>
					<name>ms5c</name>
				</author>
				<source>
					<applicationSoftware version="3.0c">Data Collector</applicationSoftware>
					<instrumentControlSoftware version="2.1A">XPERT-PRO</instrumentControlSoftware>
					<instrumentID>0000000014024241</instrumentID>
				</source>
			</header>
			<dataPoints>
				<positions axis="2Theta" unit="deg">
					<commonPosition>47.000</commonPosition>
				</positions>
				<positions axis="Omega" unit="deg">
					<commonPosition>23.500</commonPosition>
				</positions>
				<positions axis="Phi" unit="deg">
					<startPosition>0.00</startPosition>
					<endPosition>0.00</endPosition>
				</positions>
				<positions axis="Chi" unit="deg">
					<commonPosition>15.00</commonPosition>
				</positions>
				<commonCountingTime unit="seconds">2.00</commonCountingTime>
				<intensities unit="counts">1978</intensities>
			</dataPoints>
		</scan>
		<scan appendNumber="0" mode="Pre-set time" scanAxis="Phi" status="Completed">
			<header>
				<startTimeStamp>2017-08-15T02:08:47-04:00</startTimeStamp>
				<endTimeStamp>2017-08-15T02:08:49-04:00</endTimeStamp>
				<author>
					<name>ms5c</name>
				</author>
				<source>
					<applicationSoftware version="3.0c">Data Collector</applicationSoftware>
					<instrumentControlSoftware version="2.1A">XPERT-PRO</instrumentControlSoftware>
					<instrumentID>0000000014024241</instrumentID>
				</source>
			</header>
			<dataPoints>
				<positions axis="2Theta" unit="deg">
					<commonPosition>47.000</commonPosition>
				</positions>
				<positions axis="Omega" unit="deg">
					<commonPosition>23.500</commonPosition>
				</positions>
				<positions axis="Phi" unit="deg">
					<startPosition>0.00</startPosition>
					<endPosition>0.00</endPosition>
				</positions>
				<positions axis="Chi" unit="deg">
					<commonPosition>20.00</commonPosition>
				</positions>
				<commonCountingTime unit="seconds">2.00</commonCountingTime>
				<intensities unit="counts">2104</intensities>
			</dataPoints>
		</scan>
		<scan appendNumber="0" mode="Pre-set time" scanAxis="Phi" status="Completed">
			<header>
				<startTimeStamp>2017-08-15T02:08:58-04:00</startTimeStamp>
				<endTimeStamp>2017-08-15T02:09:04-04:00</endTimeStamp>
				<author>
					<name>ms5c</name>
				</author>
				<source>
					<applicationSoftware version="3.0c">Data Collector</applicationSoftware>
					<instrumentControlSoftware version="2.1A">XPERT-PRO</instrumentControlSoftware>
					<instrumentID>0000000014024241</instrumentID>
				</source>
			</header>
			<dataPoints>
				<positions axis="2Theta" unit="deg">
					<commonPosition>47.000</commonPosition>
				</positions>
				<positions axis="Omega" unit="deg">
					<commonPosition>23.500</commonPosition>
				</positions>
				<positions axis="Phi" unit="deg">
					<startPosition>0.00</startPosition>
					<endPosition>0.00</endPosition>
				</positions>
				<positions axis="Chi" unit="deg">
					<commonPosition>25.00</commonPosition>
				</positions>
				<commonCountingTime unit="seconds">2.00</commonCountingTime>
				<intensities unit="counts">1977</intensities>
			</dataPoints>
		</scan>
		<scan appendNumber="0" mode="Pre-set time" scanAxis="Phi" status="Completed">
			<header>
				<startTimeStamp>2017-08-15T02:09:13-04:00</startTimeStamp>
				<endTimeStamp>2017-08-15T02:09:16-04:00</endTimeStamp>
				<author>
					<name>ms5c</name>
				</author>
				<source>
					<applicationSoftware version="3.0c">Data Collector</applicationSoftware>
					<instrumentControlSoftware version="2.1A">XPERT-PRO</instrumentControlSoftware>
					<instrumentID>0000000014024241</instrumentID>
				</source>
			</header>
			<dataPoints>
				<positions axis="2Theta" unit="deg">
					<commonPosition>47.000</commonPosition>
				</positions>
				<positions axis="Omega" unit="deg">
					<commonPosition>23.500</commonPosition>
				</positions>
				<positions axis="Phi" unit="deg">
					<startPosition>0.00</startPosition>
					<endPosition>0.00</endPosition>
				</positions>
				<positions axis="Chi" unit="deg">
					<commonPosition>30.00</commonPosition>
				</positions>
				<commonCountingTime unit="seconds">2.00</commonCountingTime>
				<intensities unit="counts">2147</intensities>
			</dataPoints>
		</scan>
		<scan appendNumber="0" mode="Pre-set time" scanAxis="Phi" status="Completed">
			<header>
				<startTimeStamp>2017-08-15T02:09:25-04:00</startTimeStamp>
				<endTimeStamp>2017-08-15T02:09:28-04:00</endTimeStamp>
				<author>
					<name>ms5c</name>
				</author>
				<source>
					<applicationSoftware version="3.0c">Data Collector</applicationSoftware>
					<instrumentControlSoftware version="2.1A">XPERT-PRO</instrumentControlSoftware>
					<instrumentID>0000000014024241</instrumentID>
				</source>
			</header>
			<dataPoints>
				<positions axis="2Theta" unit="deg">
					<commonPosition>47.000</commonPosition>
				</positions>
				<positions axis="Omega" unit="deg">
					<commonPosition>23.500</commonPosition>
				</positions>
				<positions axis="Phi" unit="deg">
					<startPosition>0.00</startPosition>
					<endPosition>0.00</endPosition>
				</positions>
				<positions axis="Chi" unit="deg">
					<commonPosition>35.00</commonPosition>
				</positions>
				<commonCountingTime unit="seconds">2.00</commonCountingTime>
				<intensities unit="counts">2031</intensities>
			</dataPoints>
		</scan>
		<scan appendNumber="0" mode="Pre-set time" scanAxis="Phi" status="Completed">
			<header>
				<startTimeStamp>2017-08-15T02:09:36-04:00</startTimeStamp>
				<endTimeStamp>2017-08-15T02:09:38-04:00</endTimeStamp>
				<author>
					<name>ms5c</name>
				</author>
				<source>
					<applicationSoftware version="3.0c">Data Collector</applicationSoftware>
					<instrumentControlSoftware version="2.1A">XPERT-PRO</instrumentControlSoftware>
					<instrumentID>0000000014024241</instrumentID>
				</source>
			</header>
			<dataPoints>
				<positions axis="2Theta" unit="deg">
					<commonPosition>47.000</commonPosition>
				</positions>
				<positions axis="Omega" unit="deg">
					<commonPosition>23.500</commonPosition>
				</positions>
				<positions axis="Phi" unit="deg">
					<startPosition>0.00</startPosition>
					<endPosition>0.00</endPosition>
				</positions>
				<positions axis="Chi" unit="deg">
					<commonPosition>40.00</commonPosition>
				</positions>
				<commonCountingTime unit="seconds">2.00</commonCountingTime>
				<intensities unit="counts">2081</intensities>
			</dataPoints>
		</scan>
		<scan appendNumber="0" mode="Pre-set time" scanAxis="Phi" status="Completed">
			<header>
				<startTimeStamp>2017-08-15T02:09:47-04:00</startTimeStamp>
				<endTimeStamp>2017-08-15T02:09:50-04:00</endTimeStamp>
				<author>
					<name>ms5c</name>
				</author>
				<source>
					<applicationSoftware version="3.0c">Data Collector</applicationSoftware>
					<instrumentControlSoftware version="2.1A">XPERT-PRO</instrumentControlSoftware>
					<instrumentID>0000000014024241</instrumentID>
				</source>
			</header>
			<dataPoints>
				<positions axis="2Theta" unit="deg">
					<commonPosition>47.000</commonPosition>
				</positions>
				<positions axis="Omega" unit="deg">
					<commonPosition>23.500</commonPosition>
				</positions>
				<positions axis="Phi" unit="deg">
					<startPosition>0.00</startPosition>
					<endPosition>0.00</endPosition>
				</positions>
				<positions axis="Chi" unit="deg">
					<commonPosition>45.00</commonPosition>
				</positions>
				<commonCountingTime unit="seconds">2.00</commonCountingTime>
				<intensities unit="counts">1956</intensities>
			</dataPoints>
		</scan>
		<scan appendNumber="0" mode="Pre-set time" scanAxis="Phi" status="Completed">
			<header>
				<startTimeStamp>2017-08-15T02:09:58-04:00</startTimeStamp>
				<endTimeStamp>2017-08-15T02:10:04-04:00</endTimeStamp>
				<author>
					<name>ms5c</name>
				</author>
				<source>
					<applicationSoftware version="3.0c">Data Collector</applicationSoftware>
					<instrumentControlSoftware version="2.1A">XPERT-PRO</instrumentControlSoftware>
					<instrumentID>0000000014024241</instrumentID>
				</source>
			</header>
			<dataPoints>
				<positions axis="2Theta" unit="deg">
					<commonPosition>47.000</commonPosition>
				</positions>
				<positions axis="Omega" unit="deg">
					<commonPosition>23.500</commonPosition>
				</positions>
				<positions axis="Phi" unit="deg">
					<startPosition>0.00</startPosition>
					<endPosition>0.00</endPosition>
				</positions>
				<positions axis="Chi" unit="deg">
					<commonPosition>50.00</commonPosition>
				</positions>
				<commonCountingTime unit="seconds">2.00</commonCountingTime>
				<intensities unit="counts">2008</intensities>
			</dataPoints>
		</scan>
		<scan appendNumber="0" mode="Pre-set time" scanAxis="Phi" status="Completed">
			<header>
				<startTimeStamp>2017-08-15T02:10:12-04:00</startTimeStamp>
				<endTimeStamp>2017-08-15T02:10:15-04:00</endTimeStamp>
				<author>
					<name>ms5c</name>
				</author>
				<source>
					<applicationSoftware version="3.0c">Data Collector</applicationSoftware>
					<instrumentControlSoftware version="2.1A">XPERT-PRO</instrumentControlSoftware>
					<instrumentID>0000000014024241</instrumentID>
				</source>
			</header>
			<dataPoints>
				<positions axis="2Theta" unit="deg">
					<commonPosition>47.000</commonPosition>
				</positions>
				<positions axis="Omega" unit="deg">
					<commonPosition>23.500</commonPosition>
				</positions>
				<positions axis="Phi" unit="deg">
					<startPosition>0.00</startPosition>
					<endPosition>0.00</endPosition>
				</positions>
				<positions axis="Chi" unit="deg">
					<commonPosition>55.00</commonPosition>
				</positions>
				<commonCountingTime unit="seconds">2.00</commonCountingTime>
				<intensities unit="counts">2011</intensities>
			</dataPoints>
		</scan>
		<scan appendNumber="0" mode="Pre-set time" scanAxis="Phi" status="Completed">
			<header>
				<startTimeStamp>2017-08-15T02:10:23-04:00</startTimeStamp>
				<endTimeStamp>2017-08-15T02:10:26-04:00</endTimeStamp>
				<author>
					<name>ms5c</name>
				</author>
				<source>
					<applicationSoftware version="3.0c">Data Collector</applicationSoftware>
					<instrumentControlSoftware version="2.1A">XPERT-PRO</instrumentControlSoftware>
					<instrumentID>0000000014024241</instrumentID>
				</source>
			</header>
			<dataPoints>
				<positions axis="2Theta" unit="deg">
					<commonPosition>47.000</commonPosition>
				</positions>
				<positions axis="Omega" unit="deg">
					<commonPosition>23.500</commonPosition>
				</positions>
				<positions axis="Phi" unit="deg">
					<startPosition>0.00</startPosition>
					<endPosition>0.00</endPosition>
				</positions>
				<positions axis="Chi" unit="deg">
					<commonPosition>60.00</commonPosition>
				</positions>
				<commonCountingTime unit="seconds">2.00</commonCountingTime>
				<intensities unit="counts">2011</intensities>
			</dataPoints>
		</scan>
		<scan appendNumber="0" mode="Pre-set time" scanAxis="Phi" status="Completed">
			<header>
				<startTimeStamp>2017-08-15T02:10:34-04:00</startTimeStamp>
				<endTimeStamp>2017-08-15T02:10:37-04:00</endTimeStamp>
				<author>
					<name>ms5c</name>
				</author>
				<source>
					<applicationSoftware version="3.0c">Data Collector</applicationSoftware>
					<instrumentControlSoftware version="2.1A">XPERT-PRO</instrumentControlSoftware>
					<instrumentID>0000000014024241</instrumentID>
				</source>
			</header>
			<dataPoints>
				<positions axis="2Theta" unit="deg">
					<commonPosition>47.000</commonPosition>
				</positions>
				<positions axis="Omega" unit="deg">
					<commonPosition>23.500</commonPosition>
				</positions>
				<positions axis="Phi" unit="deg">
					<startPosition>0.00</startPosition>
					<endPosition>0.00</endPosition>
				</positions>
				<positions axis="Chi" unit="deg">
					<commonPosition>65.00</commonPosition>
				</positions>
				<commonCountingTime unit="seconds">2.00</commonCountingTime>
				<intensities unit="counts">1975</intensities>
			</dataPoints>
		</scan>
		<scan appendNumber="0" mode="Pre-set time" scanAxis="Phi" status="Completed">
			<header>
				<startTimeStamp>2017-08-15T02:10:42-04:00</startTimeStamp>
				<endTimeStamp>2017-08-15T02:10:44-04:00</endTimeStamp>
				<author>
					<name>ms5c</name>
				</author>
				<source>
					<applicationSoftware version="3.0c">Data Collector</applicationSoftware>
					<instrumentControlSoftware version="2.1A">XPERT-PRO</instrumentControlSoftware>
					<instrumentID>0000000014024241</instrumentID>
				</source>
			</header>
			<dataPoints>
				<positions axis="2Theta" unit="deg">
					<commonPosition>47.000</commonPosition>
				</positions>
				<positions axis="Omega" unit="deg">
					<commonPosition>23.500</commonPosition>
				</positions>
				<positions axis="Phi" unit="deg">
					<startPosition>0.00</startPosition>
					<endPosition>0.00</endPosition>
				</positions>
				<positions axis="Chi" unit="deg">
					<commonPosition>70.00</commonPosition>
				</positions>
				<commonCountingTime unit="seconds">2.00</commonCountingTime>
				<intensities unit="counts">1883</intensities>
			</dataPoints>
		</scan>
		<scan appendNumber="0" mode="Pre-set time" scanAxis="Phi" status="Completed">
			<header>
				<startTimeStamp>2017-08-15T02:10:53-04:00</startTimeStamp>
				<endTimeStamp>2017-08-15T02:10:56-04:00</endTimeStamp>
				<author>
					<name>ms5c</name>
				</author>
				<source>
					<applicationSoftware version="3.0c">Data Collector</applicationSoftware>
					<instrumentControlSoftware version="2.1A">XPERT-PRO</instrumentControlSoftware>
					<instrumentID>0000000014024241</instrumentID>
				</source>
			</header>
			<dataPoints>
				<positions axis="2Theta" unit="deg">
					<commonPosition>47.000</commonPosition>
				</positions>
				<positions axis="Omega" unit="deg">
					<commonPosition>23.500</commonPosition>
				</positions>
				<positions axis="Phi" unit="deg">
					<startPosition>0.00</startPosition>
					<endPosition>0.00</endPosition>
				</positions>
				<positions axis="Chi" unit="deg">
					<commonPosition>75.00</commonPosition>
				</positions>
				<commonCountingTime unit="seconds">2.00</commonCountingTime>
				<intensities unit="counts">1736</intensities>
			</dataPoints>
		</scan>
		<scan appendNumber="0" mode="Pre-set time" scanAxis="Phi" status="Completed">
			<header>
				<startTimeStamp>2017-08-15T02:11:01-04:00</startTimeStamp>
				<endTimeStamp>2017-08-15T02:11:04-04:00</endTimeStamp>
				<author>
					<name>ms5c</name>
				</author>
				<source>
					<applicationSoftware version="3.0c">Data Collector</applicationSoftware>
					<instrumentControlSoftware version="2.1A">XPERT-PRO</instrumentControlSoftware>
					<instrumentID>0000000014024241</instrumentID>
				</source>
			</header>
			<dataPoints>
				<positions axis="2Theta" unit="deg">
					<commonPosition>47.000</commonPosition>
				</positions>
				<positions axis="Omega" unit="deg">
					<commonPosition>23.500</commonPosition>
				</positions>
				<positions axis="Phi" unit="deg">
					<startPosition>0.00</startPosition>
					<endPosition>0.00</endPosition>
				</positions>
				<positions axis="Chi" unit="deg">
					<commonPosition>80.00</commonPosition>
				</positions>
				<commonCountingTime unit="seconds">2.00</commonCountingTime>
				<intensities unit="counts">1329</intensities>
			</dataPoints>
		</scan>
	</xrdMeasurement>
</xrdMeasurements>