File: Data/ARL/Fulin/Timet-18/Timet-18_absolutue-TD-mid.csv
[Measurement conditions]
Sample identification,
Comment - 1,"Configuration=Sample Spinner, Owner=User-1, Creation date=5/26/2011 3:50:48 PM"
Comment - 2,"Goniometer=PW3050/60 (Theta/Theta); Minimum step size 2Theta:0.001; Minimum step size Omega:0.001"
Comment - 3,"Sample stage=Spinner PW3064"
Comment - 4,"Diffractometer system=XPERT-PRO"
Comment - 5,"Measurement program=Ti_absolute, Owner=User-1, Creation date=8/11/2017 3:56:34 PM"
Anode material,Cu
K-Alpha1 wavelength,1.5405980
K-Alpha2 wavelength,1.5444260
Ratio K-Alpha2/K-Alpha1,0.500
Divergence slit,Fixed,0.5
Monochromator used,NO
Generator voltage, 45
Tube current, 40
File date and time,14/Aug/2017 16:31
Unit cell,
h k l, 0 0 0
Scan axis,Gonio
Scan range,29.996000003,124.999564637
Scan step size,0.0083556
No. of points, 11370
Scan type,CONTINUOUS
Time per step,19.685
[Scan points]
Angle,Intensity
30.000177820,78.0
30.067022896,81.0
30.133867973,91.0
30.200713049,80.0
30.267558125,84.0
30.334403201,77.0
30.401248278,86.0
30.468093354,88.0
30.534938430,91.0
30.601783506,83.0
30.668628583,77.0
30.735473659,67.0
30.802318735,79.0
30.869163811,71.0
30.936008888,84.0
31.002853964,83.0
31.069699040,87.0
31.136544116,103.0
31.203389193,58.0
31.270234269,66.0
31.337079345,90.0
31.403924421,72.0
31.470769498,88.0
31.537614574,73.0
31.604459650,71.0
31.671304727,81.0
31.738149803,80.0
31.804994879,81.0
31.871839955,77.0
31.938685032,91.0
32.005530108,86.0
32.072375184,78.0
32.139220260,71.0
32.206065337,90.0
32.272910413,68.0
32.339755489,88.0
32.406600565,73.0
32.473445642,73.0
32.540290718,81.0
32.607135794,77.0
32.673980870,72.0
32.740825947,77.0
32.807671023,92.0
32.874516099,78.0
32.941361175,62.0
33.008206252,61.0
33.075051328,72.0
33.141896404,61.0
33.208741480,70.0
33.275586557,74.0
33.342431633,95.0
33.409276709,80.0
33.476121786,73.0
33.542966862,51.0
33.609811938,59.0
33.676657014,69.0
33.743502091,59.0
33.810347167,77.0
33.877192243,72.0
33.944037319,80.0
34.010882396,70.0
34.077727472,49.0
34.144572548,91.0
34.211417624,60.0
34.278262701,79.0
34.345107777,64.0
34.411952853,77.0
34.478797929,65.0
34.545643006,78.0
34.612488082,69.0
34.679333158,91.0
34.746178234,82.0
34.813023311,74.0
34.879868387,74.0
34.946713463,64.0
35.013558540,97.0
35.080403616,92.0
35.147248692,104.0
35.214093768,162.0
35.280938845,201.0
35.347783921,313.0
35.414628997,480.0
35.481474073,810.0
35.548319150,731.0
35.615164226,607.0
35.682009302,308.0
35.748854378,171.0
35.815699455,126.0
35.882544531,95.0
35.949389607,90.0
36.016234683,94.0
36.083079760,64.0
36.149924836,85.0
36.216769912,78.0
36.283614988,85.0
36.350460065,71.0
36.417305141,72.0
36.484150217,94.0
36.550995293,75.0
36.617840370,75.0
36.684685446,79.0
36.751530522,77.0
36.818375599,65.0
36.885220675,80.0
36.952065751,69.0
37.018910827,73.0
37.085755904,71.0
37.152600980,67.0
37.219446056,82.0
37.286291132,80.0
37.353136209,97.0
37.419981285,70.0
37.486826361,96.0
37.553671437,93.0
37.620516514,75.0
37.687361590,74.0
37.754206666,93.0
37.821051742,91.0
37.887896819,90.0
37.954741895,129.0
38.021586971,136.0
38.088432047,108.0
38.155277124,163.0
38.222122200,201.0
38.288967276,260.0
38.355812353,438.0
38.422657429,732.0
38.489502505,1498.0
38.556347581,2909.0
38.623192658,2403.0
38.690037734,1794.0
38.756882810,673.0
38.823727886,416.0
38.890572963,275.0
38.957418039,294.0
39.024263115,306.0
39.091108191,406.0
39.157953268,498.0
39.224798344,706.0
39.291643420,1065.0
39.358488496,1712.0
39.425333573,2795.0
39.492178649,4959.0
39.559023725,8890.0
39.625868801,12908.0
39.692713878,10255.0
39.759558954,6365.0
39.826404030,2748.0
39.893249106,1287.0
39.960094183,756.0
40.026939259,531.0
40.093784335,476.0
40.160629412,433.0
40.227474488,491.0
40.294319564,703.0
40.361164640,934.0
40.428009717,1544.0
40.494854793,2379.0
40.561699869,3547.0
40.628544945,2538.0
40.695390022,1649.0
40.762235098,706.0
40.829080174,370.0
40.895925250,270.0
40.962770327,159.0
41.029615403,155.0
41.096460479,132.0
41.163305555,120.0
41.230150632,122.0
41.296995708,95.0
41.363840784,99.0
41.430685860,104.0
41.497530937,97.0
41.564376013,106.0
41.631221089,87.0
41.698066166,84.0
41.764911242,86.0
41.831756318,74.0
41.898601394,98.0
41.965446471,80.0
42.032291547,90.0
42.099136623,65.0
42.165981699,70.0
42.232826776,78.0
42.299671852,83.0
42.366516928,72.0
42.433362004,79.0
42.500207081,69.0
42.567052157,72.0
42.633897233,69.0
42.700742309,74.0
42.767587386,78.0
42.834432462,56.0
42.901277538,80.0
42.968122614,62.0
43.034967691,80.0
43.101812767,90.0
43.168657843,67.0
43.235502919,65.0
43.302347996,64.0
43.369193072,67.0
43.436038148,71.0
43.502883225,54.0
43.569728301,67.0
43.636573377,70.0
43.703418453,62.0
43.770263530,52.0
43.837108606,64.0
43.903953682,59.0
43.970798758,62.0
44.037643835,66.0
44.104488911,72.0
44.171333987,69.0
44.238179063,40.0
44.305024140,59.0
44.371869216,52.0
44.438714292,53.0
44.505559368,53.0
44.572404445,52.0
44.639249521,55.0
44.706094597,47.0
44.772939673,55.0
44.839784750,43.0
44.906629826,65.0
44.973474902,57.0
45.040319979,42.0
45.107165055,53.0
45.174010131,60.0
45.240855207,61.0
45.307700284,39.0
45.374545360,39.0
45.441390436,56.0
45.508235512,60.0
45.575080589,45.0
45.641925665,29.0
45.708770741,45.0
45.775615817,54.0
45.842460894,49.0
45.909305970,44.0
45.976151046,48.0
46.042996122,54.0
46.109841199,31.0
46.176686275,40.0
46.243531351,40.0
46.310376427,51.0
46.377221504,46.0
46.444066580,45.0
46.510911656,57.0
46.577756732,42.0
46.644601809,51.0
46.711446885,42.0
46.778291961,37.0
46.845137038,58.0
46.911982114,41.0
46.978827190,42.0
47.045672266,44.0
47.112517343,40.0
47.179362419,54.0
47.246207495,47.0
47.313052571,49.0
47.379897648,56.0
47.446742724,45.0
47.513587800,43.0
47.580432876,39.0
47.647277953,47.0
47.714123029,52.0
47.780968105,49.0
47.847813181,53.0
47.914658258,34.0
47.981503334,51.0
48.048348410,35.0
48.115193486,42.0
48.182038563,33.0
48.248883639,42.0
48.315728715,30.0
48.382573792,46.0
48.449418868,45.0
48.516263944,48.0
48.583109020,37.0
48.649954097,55.0
48.716799173,34.0
48.783644249,30.0
48.850489325,45.0
48.917334402,41.0
48.984179478,29.0
49.051024554,35.0
49.117869630,34.0
49.184714707,33.0
49.251559783,47.0
49.318404859,51.0
49.385249935,45.0
49.452095012,36.0
49.518940088,49.0
49.585785164,49.0
49.652630240,39.0
49.719475317,36.0
49.786320393,49.0
49.853165469,34.0
49.920010545,42.0
49.986855622,35.0
50.053700698,34.0
50.120545774,32.0
50.187390851,53.0
50.254235927,32.0
50.321081003,40.0
50.387926079,35.0
50.454771156,46.0
50.521616232,41.0
50.588461308,43.0
50.655306384,40.0
50.722151461,28.0
50.788996537,49.0
50.855841613,40.0
50.922686689,37.0
50.989531766,40.0
51.056376842,55.0
51.123221918,29.0
51.190066994,30.0
51.256912071,44.0
51.323757147,34.0
51.390602223,44.0
51.457447299,39.0
51.524292376,39.0
51.591137452,30.0
51.657982528,36.0
51.724827605,44.0
51.791672681,29.0
51.858517757,45.0
51.925362833,30.0
51.992207910,48.0
52.059052986,39.0
52.125898062,36.0
52.192743138,35.0
52.259588215,31.0
52.326433291,37.0
52.393278367,30.0
52.460123443,39.0
52.526968520,33.0
52.593813596,29.0
52.660658672,40.0
52.727503748,35.0
52.794348825,52.0
52.861193901,40.0
52.928038977,60.0
52.994884053,34.0
53.061729130,44.0
53.128574206,60.0
53.195419282,60.0
53.262264358,87.0
53.329109435,120.0
53.395954511,128.0
53.462799587,116.0
53.529644664,124.0
53.596489740,64.0
53.663334816,46.0
53.730179892,51.0
53.797024969,40.0
53.863870045,47.0
53.930715121,31.0
53.997560197,33.0
54.064405274,44.0
54.131250350,34.0
54.198095426,57.0
54.264940502,43.0
54.331785579,42.0
54.398630655,34.0
54.465475731,39.0
54.532320807,42.0
54.599165884,48.0
54.666010960,32.0
54.732856036,33.0
54.799701112,28.0
54.866546189,26.0
54.933391265,32.0
55.000236341,49.0
55.067081418,35.0
55.133926494,23.0
55.200771570,29.0
55.267616646,42.0
55.334461723,45.0
55.401306799,41.0
55.468151875,32.0
55.534996951,42.0
55.601842028,36.0
55.668687104,54.0
55.735532180,28.0
55.802377256,40.0
55.869222333,43.0
55.936067409,43.0
56.002912485,42.0
56.069757561,37.0
56.136602638,35.0
56.203447714,36.0
56.270292790,46.0
56.337137866,41.0
56.403982943,37.0
56.470828019,44.0
56.537673095,57.0
56.604518171,42.0
56.671363248,45.0
56.738208324,46.0
56.805053400,48.0
56.871898477,60.0
56.938743553,73.0
57.005588629,70.0
57.072433705,81.0
57.139278782,110.0
57.206123858,135.0
57.272968934,193.0
57.339814010,130.0
57.406659087,130.0
57.473504163,81.0
57.540349239,74.0
57.607194315,55.0
57.674039392,49.0
57.740884468,48.0
57.807729544,39.0
57.874574620,29.0
57.941419697,31.0
58.008264773,34.0
58.075109849,40.0
58.141954925,34.0
58.208800002,31.0
58.275645078,36.0
58.342490154,33.0
58.409335231,34.0
58.476180307,35.0
58.543025383,33.0
58.609870459,36.0
58.676715536,46.0
58.743560612,34.0
58.810405688,37.0
58.877250764,37.0
58.944095841,41.0
59.010940917,45.0
59.077785993,34.0
59.144631069,30.0
59.211476146,23.0
59.278321222,29.0
59.345166298,35.0
59.412011374,54.0
59.478856451,30.0
59.545701527,33.0
59.612546603,41.0
59.679391679,23.0
59.746236756,33.0
59.813081832,29.0
59.879926908,32.0
59.946771984,28.0
60.013617061,26.0
60.080462137,28.0
60.147307213,32.0
60.214152290,35.0
60.280997366,43.0
60.347842442,23.0
60.414687518,28.0
60.481532595,30.0
60.548377671,24.0
60.615222747,23.0
60.682067823,31.0
60.748912900,21.0
60.815757976,24.0
60.882603052,30.0
60.949448128,26.0
61.016293205,34.0
61.083138281,34.0
61.149983357,28.0
61.216828433,29.0
61.283673510,41.0
61.350518586,32.0
61.417363662,29.0
61.484208738,24.0
61.551053815,33.0
61.617898891,22.0
61.684743967,28.0
61.751589044,31.0
61.818434120,27.0
61.885279196,32.0
61.952124272,23.0
62.018969349,23.0
62.085814425,29.0
62.152659501,32.0
62.219504577,30.0
62.286349654,29.0
62.353194730,41.0
62.420039806,33.0
62.486884882,33.0
62.553729959,31.0
62.620575035,34.0
62.687420111,36.0
62.754265187,34.0
62.821110264,27.0
62.887955340,31.0
62.954800416,37.0
63.021645492,28.0
63.088490569,35.0
63.155335645,45.0
63.222180721,41.0
63.289025797,33.0
63.355870874,39.0
63.422715950,51.0
63.489561026,55.0
63.556406103,44.0
63.623251179,52.0
63.690096255,70.0
63.756941331,56.0
63.823786408,48.0
63.890631484,39.0
63.957476560,52.0
64.024321636,39.0
64.091166713,52.0
64.158011789,27.0
64.224856865,41.0
64.291701941,27.0
64.358547018,24.0
64.425392094,32.0
64.492237170,28.0
64.559082246,29.0
64.625927323,31.0
64.692772399,21.0
64.759617475,27.0
64.826462551,33.0
64.893307628,35.0
64.960152704,27.0
65.026997780,29.0
65.093842857,22.0
65.160687933,32.0
65.227533009,31.0
65.294378085,36.0
65.361223162,28.0
65.428068238,30.0
65.494913314,22.0
65.561758390,23.0
65.628603467,40.0
65.695448543,31.0
65.762293619,31.0
65.829138695,26.0
65.895983772,21.0
65.962828848,34.0
66.029673924,29.0
66.096519000,32.0
66.163364077,27.0
66.230209153,22.0
66.297054229,18.0
66.363899305,26.0
66.430744382,19.0
66.497589458,29.0
66.564434534,34.0
66.631279610,29.0
66.698124687,27.0
66.764969763,24.0
66.831814839,35.0
66.898659916,28.0
66.965504992,35.0
67.032350068,28.0
67.099195144,24.0
67.166040221,26.0
67.232885297,33.0
67.299730373,28.0
67.366575449,37.0
67.433420526,30.0
67.500265602,22.0
67.567110678,35.0
67.633955754,34.0
67.700800831,35.0
67.767645907,30.0
67.834490983,28.0
67.901336059,29.0
67.968181136,20.0
68.035026212,22.0
68.101871288,29.0
68.168716364,26.0
68.235561441,33.0
68.302406517,18.0
68.369251593,32.0
68.436096670,19.0
68.502941746,18.0
68.569786822,37.0
68.636631898,23.0
68.703476975,32.0
68.770322051,32.0
68.837167127,17.0
68.904012203,47.0
68.970857280,24.0
69.037702356,29.0
69.104547432,36.0
69.171392508,39.0
69.238237585,24.0
69.305082661,29.0
69.371927737,23.0
69.438772813,39.0
69.505617890,37.0
69.572462966,22.0
69.639308042,31.0
69.706153118,35.0
69.772998195,32.0
69.839843271,33.0
69.906688347,41.0
69.973533423,40.0
70.040378500,36.0
70.107223576,40.0
70.174068652,48.0
70.240913729,39.0
70.307758805,41.0
70.374603881,36.0
70.441448957,32.0
70.508294034,51.0
70.575139110,26.0
70.641984186,57.0
70.708829262,62.0
70.775674339,66.0
70.842519415,70.0
70.909364491,96.0
70.976209567,128.0
71.043054644,197.0
71.109899720,195.0
71.176744796,169.0
71.243589872,155.0
71.310434949,185.0
71.377280025,149.0
71.444125101,146.0
71.510970177,141.0
71.577815254,209.0
71.644660330,251.0
71.711505406,402.0
71.778350483,600.0
71.845195559,690.0
71.912040635,643.0
71.978885711,561.0
72.045730788,497.0
72.112575864,384.0
72.179420940,231.0
72.246266016,175.0
72.313111093,111.0
72.379956169,82.0
72.446801245,73.0
72.513646321,41.0
72.580491398,49.0
72.647336474,57.0
72.714181550,41.0
72.781026626,36.0
72.847871703,53.0
72.914716779,43.0
72.981561855,31.0
73.048406931,32.0
73.115252008,42.0
73.182097084,32.0
73.248942160,33.0
73.315787236,42.0
73.382632313,34.0
73.449477389,35.0
73.516322465,32.0
73.583167542,35.0
73.650012618,32.0
73.716857694,28.0
73.783702770,21.0
73.850547847,33.0
73.917392923,36.0
73.984237999,45.0
74.051083075,29.0
74.117928152,33.0
74.184773228,36.0
74.251618304,36.0
74.318463380,45.0
74.385308457,34.0
74.452153533,39.0
74.518998609,48.0
74.585843685,34.0
74.652688762,37.0
74.719533838,44.0
74.786378914,39.0
74.853223990,47.0
74.920069067,47.0
74.986914143,73.0
75.053759219,74.0
75.120604296,71.0
75.187449372,77.0
75.254294448,77.0
75.321139524,64.0
75.387984601,45.0
75.454829677,59.0
75.521674753,40.0
75.588519829,37.0
75.655364906,40.0
75.722209982,35.0
75.789055058,42.0
75.855900134,31.0
75.922745211,47.0
75.989590287,37.0
76.056435363,37.0
76.123280439,41.0
76.190125516,37.0
76.256970592,31.0
76.323815668,42.0
76.390660744,42.0
76.457505821,46.0
76.524350897,46.0
76.591195973,51.0
76.658041049,56.0
76.724886126,53.0
76.791731202,58.0
76.858576278,67.0
76.925421355,118.0
76.992266431,115.0
77.059111507,87.0
77.125956583,72.0
77.192801660,83.0
77.259646736,69.0
77.326491812,52.0
77.393336888,51.0
77.460181965,32.0
77.527027041,35.0
77.593872117,43.0
77.660717193,46.0
77.727562270,46.0
77.794407346,54.0
77.861252422,45.0
77.928097498,45.0
77.994942575,47.0
78.061787651,61.0
78.128632727,78.0
78.195477803,99.0
78.262322880,131.0
78.329167956,121.0
78.396013032,119.0
78.462858109,93.0
78.529703185,88.0
78.596548261,73.0
78.663393337,60.0
78.730238414,46.0
78.797083490,47.0
78.863928566,40.0
78.930773642,39.0
78.997618719,30.0
79.064463795,32.0
79.131308871,23.0
79.198153947,37.0
79.264999024,36.0
79.331844100,36.0
79.398689176,31.0
79.465534252,24.0
79.532379329,27.0
79.599224405,27.0
79.666069481,40.0
79.732914557,23.0
79.799759634,32.0
79.866604710,32.0
79.933449786,33.0
80.000294862,29.0
80.067139939,29.0
80.133985015,26.0
80.200830091,21.0
80.267675168,30.0
80.334520244,27.0
80.401365320,26.0
80.468210396,24.0
80.535055473,32.0
80.601900549,30.0
80.668745625,20.0
80.735590701,27.0
80.802435778,37.0
80.869280854,23.0
80.936125930,36.0
81.002971006,27.0
81.069816083,30.0
81.136661159,44.0
81.203506235,29.0
81.270351311,36.0
81.337196388,30.0
81.404041464,40.0
81.470886540,32.0
81.537731616,26.0
81.604576693,33.0
81.671421769,37.0
81.738266845,32.0
81.805111922,31.0
81.871956998,34.0
81.938802074,37.0
82.005647150,28.0
82.072492227,49.0
82.139337303,40.0
82.206182379,42.0
82.273027455,40.0
82.339872532,55.0
82.406717608,53.0
82.473562684,86.0
82.540407760,103.0
82.607252837,170.0
82.674097913,110.0
82.740942989,105.0
82.807788065,91.0
82.874633142,111.0
82.941478218,68.0
83.008323294,52.0
83.075168370,46.0
83.142013447,47.0
83.208858523,35.0
83.275703599,34.0
83.342548675,33.0
83.409393752,32.0
83.476238828,31.0
83.543083904,32.0
83.609928981,35.0
83.676774057,28.0
83.743619133,26.0
83.810464209,34.0
83.877309286,24.0
83.944154362,28.0
84.010999438,32.0
84.077844514,33.0
84.144689591,34.0
84.211534667,39.0
84.278379743,56.0
84.345224819,36.0
84.412069896,49.0
84.478914972,36.0
84.545760048,54.0
84.612605124,54.0
84.679450201,71.0
84.746295277,64.0
84.813140353,72.0
84.879985429,87.0
84.946830506,95.0
85.013675582,119.0
85.080520658,182.0
85.147365735,230.0
85.214210811,321.0
85.281055887,339.0
85.347900963,325.0
85.414746040,291.0
85.481591116,272.0
85.548436192,228.0
85.615281268,183.0
85.682126345,124.0
85.748971421,83.0
85.815816497,73.0
85.882661573,78.0
85.949506650,53.0
86.016351726,47.0
86.083196802,35.0
86.150041878,46.0
86.216886955,39.0
86.283732031,34.0
86.350577107,31.0
86.417422183,28.0
86.484267260,39.0
86.551112336,23.0
86.617957412,40.0
86.684802488,45.0
86.751647565,44.0
86.818492641,26.0
86.885337717,35.0
86.952182794,37.0
87.019027870,33.0
87.085872946,32.0
87.152718022,46.0
87.219563099,26.0
87.286408175,33.0
87.353253251,32.0
87.420098327,42.0
87.486943404,49.0
87.553788480,61.0
87.620633556,72.0
87.687478632,60.0
87.754323709,67.0
87.821168785,53.0
87.888013861,62.0
87.954858937,53.0
88.021704014,61.0
88.088549090,57.0
88.155394166,47.0
88.222239242,39.0
88.289084319,34.0
88.355929395,40.0
88.422774471,43.0
88.489619548,33.0
88.556464624,31.0
88.623309700,19.0
88.690154776,33.0
88.756999853,26.0
88.823844929,34.0
88.890690005,28.0
88.957535081,39.0
89.024380158,31.0
89.091225234,18.0
89.158070310,24.0
89.224915386,28.0
89.291760463,27.0
89.358605539,29.0
89.425450615,22.0
89.492295691,29.0
89.559140768,17.0
89.625985844,21.0
89.692830920,27.0
89.759675996,27.0
89.826521073,28.0
89.893366149,39.0
89.960211225,32.0
90.027056301,33.0
90.093901378,32.0
90.160746454,24.0
90.227591530,30.0
90.294436607,31.0
90.361281683,23.0
90.428126759,28.0
90.494971835,28.0
90.561816912,28.0
90.628661988,27.0
90.695507064,32.0
90.762352140,22.0
90.829197217,22.0
90.896042293,20.0
90.962887369,23.0
91.029732445,29.0
91.096577522,26.0
91.163422598,30.0
91.230267674,19.0
91.297112750,16.0
91.363957827,26.0
91.430802903,29.0
91.497647979,26.0
91.564493055,43.0
91.631338132,20.0
91.698183208,30.0
91.765028284,17.0
91.831873361,29.0
91.898718437,21.0
91.965563513,28.0
92.032408589,28.0
92.099253666,26.0
92.166098742,20.0
92.232943818,24.0
92.299788894,29.0
92.366633971,22.0
92.433479047,29.0
92.500324123,34.0
92.567169199,27.0
92.634014276,23.0
92.700859352,30.0
92.767704428,26.0
92.834549504,21.0
92.901394581,27.0
92.968239657,19.0
93.035084733,22.0
93.101929809,33.0
93.168774886,33.0
93.235619962,35.0
93.302465038,41.0
93.369310114,43.0
93.436155191,47.0
93.503000267,32.0
93.569845343,40.0
93.636690420,22.0
93.703535496,24.0
93.770380572,30.0
93.837225648,41.0
93.904070725,34.0
93.970915801,34.0
94.037760877,24.0
94.104605953,30.0
94.171451030,20.0
94.238296106,34.0
94.305141182,21.0
94.371986258,32.0
94.438831335,26.0
94.505676411,26.0
94.572521487,29.0
94.639366563,26.0
94.706211640,29.0
94.773056716,22.0
94.839901792,15.0
94.906746868,35.0
94.973591945,32.0
95.040437021,26.0
95.107282097,23.0
95.174127174,24.0
95.240972250,18.0
95.307817326,20.0
95.374662402,30.0
95.441507479,23.0
95.508352555,19.0
95.575197631,23.0
95.642042707,35.0
95.708887784,26.0
95.775732860,26.0
95.842577936,28.0
95.909423012,21.0
95.976268089,20.0
96.043113165,26.0
96.109958241,23.0
96.176803317,31.0
96.243648394,23.0
96.310493470,32.0
96.377338546,32.0
96.444183622,26.0
96.511028699,24.0
96.577873775,28.0
96.644718851,31.0
96.711563927,31.0
96.778409004,23.0
96.845254080,17.0
96.912099156,20.0
96.978944233,30.0
97.045789309,22.0
97.112634385,27.0
97.179479461,18.0
97.246324538,34.0
97.313169614,24.0
97.380014690,32.0
97.446859766,29.0
97.513704843,28.0
97.580549919,28.0
97.647394995,36.0
97.714240071,33.0
97.781085148,21.0
97.847930224,27.0
97.914775300,32.0
97.981620376,31.0
98.048465453,28.0
98.115310529,33.0
98.182155605,39.0
98.249000681,57.0
98.315845758,49.0
98.382690834,68.0
98.449535910,55.0
98.516380987,54.0
98.583226063,57.0
98.650071139,43.0
98.716916215,47.0
98.783761292,52.0
98.850606368,41.0
98.917451444,55.0
98.984296520,39.0
99.051141597,28.0
99.117986673,33.0
99.184831749,31.0
99.251676825,26.0
99.318521902,24.0
99.385366978,17.0
99.452212054,27.0
99.519057130,30.0
99.585902207,34.0
99.652747283,21.0
99.719592359,29.0
99.786437435,29.0
99.853282512,27.0
99.920127588,36.0
99.986972664,27.0
100.053817740,28.0
100.120662817,35.0
100.187507893,29.0
100.254352969,20.0
100.321198046,27.0
100.388043122,33.0
100.454888198,33.0
100.521733274,26.0
100.588578351,27.0
100.655423427,24.0
100.722268503,27.0
100.789113579,24.0
100.855958656,17.0
100.922803732,27.0
100.989648808,22.0
101.056493884,26.0
101.123338961,37.0
101.190184037,21.0
101.257029113,28.0
101.323874189,32.0
101.390719266,21.0
101.457564342,15.0
101.524409418,32.0
101.591254494,28.0
101.658099571,28.0
101.724944647,30.0
101.791789723,30.0
101.858634800,24.0
101.925479876,24.0
101.992324952,21.0
102.059170028,20.0
102.126015105,27.0
102.192860181,22.0
102.259705257,37.0
102.326550333,23.0
102.393395410,29.0
102.460240486,30.0
102.527085562,27.0
102.593930638,22.0
102.660775715,34.0
102.727620791,32.0
102.794465867,22.0
102.861310943,23.0
102.928156020,36.0
102.995001096,34.0
103.061846172,40.0
103.128691248,35.0
103.195536325,40.0
103.262381401,34.0
103.329226477,56.0
103.396071553,42.0
103.462916630,46.0
103.529761706,37.0
103.596606782,24.0
103.663451859,43.0
103.730296935,46.0
103.797142011,36.0
103.863987087,33.0
103.930832164,32.0
103.997677240,26.0
104.064522316,27.0
104.131367392,26.0
104.198212469,37.0
104.265057545,28.0
104.331902621,31.0
104.398747697,35.0
104.465592774,26.0
104.532437850,22.0
104.599282926,22.0
104.666128002,26.0
104.732973079,28.0
104.799818155,30.0
104.866663231,27.0
104.933508307,27.0
105.000353384,23.0
105.067198460,21.0
105.134043536,21.0
105.200888613,26.0
105.267733689,40.0
105.334578765,16.0
105.401423841,16.0
105.468268918,27.0
105.535113994,16.0
105.601959070,30.0
105.668804146,22.0
105.735649223,28.0
105.802494299,26.0
105.869339375,32.0
105.936184451,21.0
106.003029528,33.0
106.069874604,27.0
106.136719680,34.0
106.203564756,29.0
106.270409833,28.0
106.337254909,36.0
106.404099985,35.0
106.470945061,20.0
106.537790138,18.0
106.604635214,33.0
106.671480290,18.0
106.738325366,28.0
106.805170443,26.0
106.872015519,29.0
106.938860595,29.0
107.005705672,24.0
107.072550748,21.0
107.139395824,33.0
107.206240900,32.0
107.273085977,20.0
107.339931053,29.0
107.406776129,30.0
107.473621205,28.0
107.540466282,33.0
107.607311358,26.0
107.674156434,30.0
107.741001510,17.0
107.807846587,27.0
107.874691663,21.0
107.941536739,27.0
108.008381815,24.0
108.075226892,24.0
108.142071968,34.0
108.208917044,26.0
108.275762120,26.0
108.342607197,28.0
108.409452273,39.0
108.476297349,33.0
108.543142426,18.0
108.609987502,18.0
108.676832578,23.0
108.743677654,29.0
108.810522731,31.0
108.877367807,28.0
108.944212883,34.0
109.011057959,24.0
109.077903036,22.0
109.144748112,31.0
109.211593188,32.0
109.278438264,29.0
109.345283341,28.0
109.412128417,23.0
109.478973493,30.0
109.545818569,19.0
109.612663646,36.0
109.679508722,32.0
109.746353798,11.0
109.813198874,26.0
109.880043951,24.0
109.946889027,17.0
110.013734103,36.0
110.080579179,31.0
110.147424256,32.0
110.214269332,27.0
110.281114408,30.0
110.347959485,36.0
110.414804561,37.0
110.481649637,34.0
110.548494713,30.0
110.615339790,48.0
110.682184866,39.0
110.749029942,41.0
110.815875018,40.0
110.882720095,32.0
110.949565171,39.0
111.016410247,47.0
111.083255323,43.0
111.150100400,40.0
111.216945476,32.0
111.283790552,43.0
111.350635628,41.0
111.417480705,23.0
111.484325781,47.0
111.551170857,26.0
111.618015933,20.0
111.684861010,26.0
111.751706086,27.0
111.818551162,29.0
111.885396239,21.0
111.952241315,28.0
112.019086391,19.0
112.085931467,22.0
112.152776544,34.0
112.219621620,33.0
112.286466696,23.0
112.353311772,34.0
112.420156849,28.0
112.487001925,24.0
112.553847001,28.0
112.620692077,24.0
112.687537154,22.0
112.754382230,24.0
112.821227306,30.0
112.888072382,22.0
112.954917459,18.0
113.021762535,23.0
113.088607611,35.0
113.155452687,27.0
113.222297764,26.0
113.289142840,26.0
113.355987916,28.0
113.422832992,36.0
113.489678069,26.0
113.556523145,36.0
113.623368221,32.0
113.690213298,21.0
113.757058374,27.0
113.823903450,22.0
113.890748526,30.0
113.957593603,21.0
114.024438679,28.0
114.091283755,32.0
114.158128831,34.0
114.224973908,27.0
114.291818984,24.0
114.358664060,26.0
114.425509136,29.0
114.492354213,26.0
114.559199289,41.0
114.626044365,37.0
114.692889441,22.0
114.759734518,18.0
114.826579594,26.0
114.893424670,23.0
114.960269746,20.0
115.027114823,29.0
115.093959899,29.0
115.160804975,35.0
115.227650052,39.0
115.294495128,37.0
115.361340204,29.0
115.428185280,30.0
115.495030357,35.0
115.561875433,24.0
115.628720509,27.0
115.695565585,24.0
115.762410662,27.0
115.829255738,31.0
115.896100814,23.0
115.962945890,27.0
116.029790967,26.0
116.096636043,22.0
116.163481119,26.0
116.230326195,24.0
116.297171272,30.0
116.364016348,30.0
116.430861424,14.0
116.497706500,23.0
116.564551577,28.0
116.631396653,16.0
116.698241729,27.0
116.765086805,30.0
116.831931882,22.0
116.898776958,19.0
116.965622034,31.0
117.032467111,15.0
117.099312187,28.0
117.166157263,21.0
117.233002339,24.0
117.299847416,32.0
117.366692492,23.0
117.433537568,21.0
117.500382644,26.0
117.567227721,33.0
117.634072797,19.0
117.700917873,26.0
117.767762949,29.0
117.834608026,23.0
117.901453102,28.0
117.968298178,29.0
118.035143254,30.0
118.101988331,26.0
118.168833407,23.0
118.235678483,22.0
118.302523559,39.0
118.369368636,29.0
118.436213712,34.0
118.503058788,10.0
118.569903865,29.0
118.636748941,26.0
118.703594017,28.0
118.770439093,22.0
118.837284170,28.0
118.904129246,22.0
118.970974322,21.0
119.037819398,28.0
119.104664475,36.0
119.171509551,28.0
119.238354627,23.0
119.305199703,29.0
119.372044780,23.0
119.438889856,20.0
119.505734932,29.0
119.572580008,35.0
119.639425085,32.0
119.706270161,29.0
119.773115237,24.0
119.839960313,21.0
119.906805390,40.0
119.973650466,17.0
120.040495542,29.0
120.107340618,31.0
120.174185695,26.0
120.241030771,21.0
120.307875847,22.0
120.374720924,32.0
120.441566000,31.0
120.508411076,24.0
120.575256152,31.0
120.642101229,42.0
120.708946305,31.0
120.775791381,41.0
120.842636457,42.0
120.909481534,33.0
120.976326610,31.0
121.043171686,36.0
121.110016762,29.0
121.176861839,37.0
121.243706915,24.0
121.310551991,31.0
121.377397067,39.0
121.444242144,28.0
121.511087220,34.0
121.577932296,33.0
121.644777372,37.0
121.711622449,29.0
121.778467525,26.0
121.845312601,28.0
121.912157678,23.0
121.979002754,24.0
122.045847830,22.0
122.112692906,31.0
122.179537983,28.0
122.246383059,31.0
122.313228135,26.0
122.380073211,31.0
122.446918288,28.0
122.513763364,30.0
122.580608440,39.0
122.647453516,32.0
122.714298593,44.0
122.781143669,44.0
122.847988745,34.0
122.914833821,40.0
122.981678898,43.0
123.048523974,66.0
123.115369050,57.0
123.182214126,61.0
123.249059203,40.0
123.315904279,41.0
123.382749355,43.0
123.449594431,46.0
123.516439508,52.0
123.583284584,47.0
123.650129660,49.0
123.716974737,42.0
123.783819813,49.0
123.850664889,43.0
123.917509965,39.0
123.984355042,37.0
124.051200118,20.0
124.118045194,30.0
124.184890270,32.0
124.251735347,39.0
124.318580423,33.0
124.385425499,30.0
124.452270575,35.0
124.519115652,28.0
124.585960728,30.0
124.652805804,19.0
124.719650880,32.0
124.786495957,47.0
124.853341033,24.0
124.920186109,33.0
124.987031185,22.0
124.995386820,32.0